[2024-10-07T13:02:31.479+0000] {local_task_job_runner.py:123} INFO - ::group::Pre task execution logs
[2024-10-07T13:02:31.487+0000] {taskinstance.py:2612} INFO - Dependencies all met for dep_context=non-requeueable deps ti=<TaskInstance: csv_to_star_schema_to_s3_to_redshift.transfer_fact_sales_to_redshift manual__2024-10-07T12:56:50.914649+00:00 [queued]>
[2024-10-07T13:02:31.492+0000] {taskinstance.py:2612} INFO - Dependencies all met for dep_context=requeueable deps ti=<TaskInstance: csv_to_star_schema_to_s3_to_redshift.transfer_fact_sales_to_redshift manual__2024-10-07T12:56:50.914649+00:00 [queued]>
[2024-10-07T13:02:31.493+0000] {taskinstance.py:2865} INFO - Starting attempt 2 of 2
[2024-10-07T13:02:31.501+0000] {taskinstance.py:2888} INFO - Executing <Task(S3ToRedshiftOperator): transfer_fact_sales_to_redshift> on 2024-10-07 12:56:50.914649+00:00
[2024-10-07T13:02:31.506+0000] {logging_mixin.py:190} WARNING - /home/***/.local/lib/python3.12/site-packages/***/task/task_runner/standard_task_runner.py:70 DeprecationWarning: This process (pid=11069) is multi-threaded, use of fork() may lead to deadlocks in the child.
[2024-10-07T13:02:31.507+0000] {standard_task_runner.py:72} INFO - Started process 11071 to run task
[2024-10-07T13:02:31.507+0000] {standard_task_runner.py:104} INFO - Running: ['***', 'tasks', 'run', 'csv_to_star_schema_to_s3_to_redshift', 'transfer_fact_sales_to_redshift', 'manual__2024-10-07T12:56:50.914649+00:00', '--job-id', '137', '--raw', '--subdir', 'DAGS_FOLDER/sales_pipeline.py', '--cfg-path', '/tmp/tmpe81hv6uh']
[2024-10-07T13:02:31.508+0000] {standard_task_runner.py:105} INFO - Job 137: Subtask transfer_fact_sales_to_redshift
[2024-10-07T13:02:31.517+0000] {logging_mixin.py:190} WARNING - /home/***/.local/lib/python3.12/site-packages/***/settings.py:209 DeprecationWarning: The sql_alchemy_conn option in [core] has been moved to the sql_alchemy_conn option in [database] - the old setting has been used, but please update your config.
[2024-10-07T13:02:31.534+0000] {task_command.py:467} INFO - Running <TaskInstance: csv_to_star_schema_to_s3_to_redshift.transfer_fact_sales_to_redshift manual__2024-10-07T12:56:50.914649+00:00 [running]> on host 66045655c750
[2024-10-07T13:02:31.576+0000] {taskinstance.py:3131} INFO - Exporting env vars: AIRFLOW_CTX_DAG_OWNER='***' AIRFLOW_CTX_DAG_ID='csv_to_star_schema_to_s3_to_redshift' AIRFLOW_CTX_TASK_ID='transfer_fact_sales_to_redshift' AIRFLOW_CTX_EXECUTION_DATE='2024-10-07T12:56:50.914649+00:00' AIRFLOW_CTX_TRY_NUMBER='2' AIRFLOW_CTX_DAG_RUN_ID='manual__2024-10-07T12:56:50.914649+00:00'
[2024-10-07T13:02:31.577+0000] {taskinstance.py:731} INFO - ::endgroup::
[2024-10-07T13:02:31.594+0000] {base.py:84} INFO - Retrieving connection 'aws_default'
[2024-10-07T13:02:31.598+0000] {base.py:84} INFO - Retrieving connection 'aws_default'
[2024-10-07T13:02:31.599+0000] {connection_wrapper.py:388} INFO - AWS Connection (conn_id='aws_default', conn_type='aws') credentials retrieved from login and password.
[2024-10-07T13:02:31.605+0000] {s3_to_redshift.py:194} INFO - Executing COPY command...
[2024-10-07T13:02:31.610+0000] {base.py:84} INFO - Retrieving connection 'redshift_default'
[2024-10-07T13:02:31.614+0000] {base.py:84} INFO - Retrieving connection 'aws_default'
[2024-10-07T13:02:31.615+0000] {connection_wrapper.py:388} INFO - AWS Connection (conn_id='aws_default', conn_type='aws') credentials retrieved from login and password.
[2024-10-07T13:02:32.958+0000] {credentials.py:1147} INFO - Found credentials in environment variables.
[2024-10-07T13:02:34.880+0000] {sql.py:509} INFO - Running statement: 
                    COPY etl_data.fact_sales 
                    FROM 's3://finalprojectdibimbing/data/fact_sales.csv'
                    credentials
                    'aws_access_key_id=AKIATL6XMQFJ5UANYFMX;aws_secret_access_key=***'
                    
                    CSV
			IGNOREHEADER 1;
        , parameters: None
[2024-10-07T13:02:35.511+0000] {taskinstance.py:3310} ERROR - Task failed with exception
Traceback (most recent call last):
  File "/home/airflow/.local/lib/python3.12/site-packages/airflow/models/taskinstance.py", line 767, in _execute_task
    result = _execute_callable(context=context, **execute_callable_kwargs)
             ^^^^^^^^^^^^^^^^^^^^^^^^^^^^^^^^^^^^^^^^^^^^^^^^^^^^^^^^^^^^^
  File "/home/airflow/.local/lib/python3.12/site-packages/airflow/models/taskinstance.py", line 733, in _execute_callable
    return ExecutionCallableRunner(
           ^^^^^^^^^^^^^^^^^^^^^^^^
  File "/home/airflow/.local/lib/python3.12/site-packages/airflow/utils/operator_helpers.py", line 252, in run
    return self.func(*args, **kwargs)
           ^^^^^^^^^^^^^^^^^^^^^^^^^^
  File "/home/airflow/.local/lib/python3.12/site-packages/airflow/models/baseoperator.py", line 406, in wrapper
    return func(self, *args, **kwargs)
           ^^^^^^^^^^^^^^^^^^^^^^^^^^^
  File "/home/airflow/.local/lib/python3.12/site-packages/airflow/providers/amazon/aws/transfers/s3_to_redshift.py", line 198, in execute
    redshift_hook.run(sql, autocommit=self.autocommit)
  File "/home/airflow/.local/lib/python3.12/site-packages/airflow/providers/common/sql/hooks/sql.py", line 456, in run
    self._run_command(cur, sql_statement, parameters)
  File "/home/airflow/.local/lib/python3.12/site-packages/airflow/providers/common/sql/hooks/sql.py", line 514, in _run_command
    cur.execute(sql_statement)
  File "/home/airflow/.local/lib/python3.12/site-packages/redshift_connector/cursor.py", line 248, in execute
    raise e
  File "/home/airflow/.local/lib/python3.12/site-packages/redshift_connector/cursor.py", line 241, in execute
    self._c.execute(self, operation, args)
  File "/home/airflow/.local/lib/python3.12/site-packages/redshift_connector/core.py", line 1996, in execute
    self.handle_messages(cursor)
  File "/home/airflow/.local/lib/python3.12/site-packages/redshift_connector/core.py", line 2203, in handle_messages
    raise self.error
redshift_connector.error.ProgrammingError: {'S': 'ERROR', 'C': 'XX000', 'M': "Load into table 'fact_sales' failed.  Check 'sys_load_error_detail' system table for details.", 'F': '/home/ec2-user/padb/src/pg/src/backend/commands/commands_copy.c', 'L': '769', 'R': 'CheckMaxRowError'}
[2024-10-07T13:02:35.517+0000] {taskinstance.py:1225} INFO - Marking task as FAILED. dag_id=csv_to_star_schema_to_s3_to_redshift, task_id=transfer_fact_sales_to_redshift, run_id=manual__2024-10-07T12:56:50.914649+00:00, execution_date=20241007T125650, start_date=20241007T130231, end_date=20241007T130235
[2024-10-07T13:02:35.525+0000] {taskinstance.py:340} INFO - ::group::Post task execution logs
[2024-10-07T13:02:35.525+0000] {standard_task_runner.py:124} ERROR - Failed to execute job 137 for task transfer_fact_sales_to_redshift ({'S': 'ERROR', 'C': 'XX000', 'M': "Load into table 'fact_sales' failed.  Check 'sys_load_error_detail' system table for details.", 'F': '/home/ec2-user/padb/src/pg/src/backend/commands/commands_copy.c', 'L': '769', 'R': 'CheckMaxRowError'}; 11071)
Traceback (most recent call last):
  File "/home/airflow/.local/lib/python3.12/site-packages/airflow/task/task_runner/standard_task_runner.py", line 117, in _start_by_fork
    ret = args.func(args, dag=self.dag)
          ^^^^^^^^^^^^^^^^^^^^^^^^^^^^^
  File "/home/airflow/.local/lib/python3.12/site-packages/airflow/cli/cli_config.py", line 49, in command
    return func(*args, **kwargs)
           ^^^^^^^^^^^^^^^^^^^^^
  File "/home/airflow/.local/lib/python3.12/site-packages/airflow/utils/cli.py", line 115, in wrapper
    return f(*args, **kwargs)
           ^^^^^^^^^^^^^^^^^^
  File "/home/airflow/.local/lib/python3.12/site-packages/airflow/cli/commands/task_command.py", line 483, in task_run
    task_return_code = _run_task_by_selected_method(args, _dag, ti)
                       ^^^^^^^^^^^^^^^^^^^^^^^^^^^^^^^^^^^^^^^^^^^^
  File "/home/airflow/.local/lib/python3.12/site-packages/airflow/cli/commands/task_command.py", line 256, in _run_task_by_selected_method
    return _run_raw_task(args, ti)
           ^^^^^^^^^^^^^^^^^^^^^^^
  File "/home/airflow/.local/lib/python3.12/site-packages/airflow/cli/commands/task_command.py", line 341, in _run_raw_task
    return ti._run_raw_task(
           ^^^^^^^^^^^^^^^^^
  File "/home/airflow/.local/lib/python3.12/site-packages/airflow/utils/session.py", line 97, in wrapper
    return func(*args, session=session, **kwargs)
           ^^^^^^^^^^^^^^^^^^^^^^^^^^^^^^^^^^^^^^
  File "/home/airflow/.local/lib/python3.12/site-packages/airflow/models/taskinstance.py", line 3004, in _run_raw_task
    return _run_raw_task(
           ^^^^^^^^^^^^^^
  File "/home/airflow/.local/lib/python3.12/site-packages/airflow/models/taskinstance.py", line 273, in _run_raw_task
    TaskInstance._execute_task_with_callbacks(
  File "/home/airflow/.local/lib/python3.12/site-packages/airflow/models/taskinstance.py", line 3158, in _execute_task_with_callbacks
    result = self._execute_task(context, task_orig)
             ^^^^^^^^^^^^^^^^^^^^^^^^^^^^^^^^^^^^^^
  File "/home/airflow/.local/lib/python3.12/site-packages/airflow/models/taskinstance.py", line 3182, in _execute_task
    return _execute_task(self, context, task_orig)
           ^^^^^^^^^^^^^^^^^^^^^^^^^^^^^^^^^^^^^^^
  File "/home/airflow/.local/lib/python3.12/site-packages/airflow/models/taskinstance.py", line 767, in _execute_task
    result = _execute_callable(context=context, **execute_callable_kwargs)
             ^^^^^^^^^^^^^^^^^^^^^^^^^^^^^^^^^^^^^^^^^^^^^^^^^^^^^^^^^^^^^
  File "/home/airflow/.local/lib/python3.12/site-packages/airflow/models/taskinstance.py", line 733, in _execute_callable
    return ExecutionCallableRunner(
           ^^^^^^^^^^^^^^^^^^^^^^^^
  File "/home/airflow/.local/lib/python3.12/site-packages/airflow/utils/operator_helpers.py", line 252, in run
    return self.func(*args, **kwargs)
           ^^^^^^^^^^^^^^^^^^^^^^^^^^
  File "/home/airflow/.local/lib/python3.12/site-packages/airflow/models/baseoperator.py", line 406, in wrapper
    return func(self, *args, **kwargs)
           ^^^^^^^^^^^^^^^^^^^^^^^^^^^
  File "/home/airflow/.local/lib/python3.12/site-packages/airflow/providers/amazon/aws/transfers/s3_to_redshift.py", line 198, in execute
    redshift_hook.run(sql, autocommit=self.autocommit)
  File "/home/airflow/.local/lib/python3.12/site-packages/airflow/providers/common/sql/hooks/sql.py", line 456, in run
    self._run_command(cur, sql_statement, parameters)
  File "/home/airflow/.local/lib/python3.12/site-packages/airflow/providers/common/sql/hooks/sql.py", line 514, in _run_command
    cur.execute(sql_statement)
  File "/home/airflow/.local/lib/python3.12/site-packages/redshift_connector/cursor.py", line 248, in execute
    raise e
  File "/home/airflow/.local/lib/python3.12/site-packages/redshift_connector/cursor.py", line 241, in execute
    self._c.execute(self, operation, args)
  File "/home/airflow/.local/lib/python3.12/site-packages/redshift_connector/core.py", line 1996, in execute
    self.handle_messages(cursor)
  File "/home/airflow/.local/lib/python3.12/site-packages/redshift_connector/core.py", line 2203, in handle_messages
    raise self.error
redshift_connector.error.ProgrammingError: {'S': 'ERROR', 'C': 'XX000', 'M': "Load into table 'fact_sales' failed.  Check 'sys_load_error_detail' system table for details.", 'F': '/home/ec2-user/padb/src/pg/src/backend/commands/commands_copy.c', 'L': '769', 'R': 'CheckMaxRowError'}
[2024-10-07T13:02:35.535+0000] {local_task_job_runner.py:266} INFO - Task exited with return code 1
[2024-10-07T13:02:35.543+0000] {taskinstance.py:3900} INFO - 0 downstream tasks scheduled from follow-on schedule check
[2024-10-07T13:02:35.546+0000] {local_task_job_runner.py:245} INFO - ::endgroup::
