[2024-10-07T12:52:50.308+0000] {local_task_job_runner.py:123} INFO - ::group::Pre task execution logs
[2024-10-07T12:52:50.316+0000] {taskinstance.py:2612} INFO - Dependencies all met for dep_context=non-requeueable deps ti=<TaskInstance: csv_to_star_schema_to_s3_to_redshift.create_or_replace_fact_sales_table manual__2024-10-07T12:52:42.125159+00:00 [queued]>
[2024-10-07T12:52:50.321+0000] {taskinstance.py:2612} INFO - Dependencies all met for dep_context=requeueable deps ti=<TaskInstance: csv_to_star_schema_to_s3_to_redshift.create_or_replace_fact_sales_table manual__2024-10-07T12:52:42.125159+00:00 [queued]>
[2024-10-07T12:52:50.321+0000] {taskinstance.py:2865} INFO - Starting attempt 1 of 2
[2024-10-07T12:52:50.330+0000] {taskinstance.py:2888} INFO - Executing <Task(SQLExecuteQueryOperator): create_or_replace_fact_sales_table> on 2024-10-07 12:52:42.125159+00:00
[2024-10-07T12:52:50.334+0000] {logging_mixin.py:190} WARNING - /home/***/.local/lib/python3.12/site-packages/***/task/task_runner/standard_task_runner.py:70 DeprecationWarning: This process (pid=10722) is multi-threaded, use of fork() may lead to deadlocks in the child.
[2024-10-07T12:52:50.335+0000] {standard_task_runner.py:72} INFO - Started process 10730 to run task
[2024-10-07T12:52:50.335+0000] {standard_task_runner.py:104} INFO - Running: ['***', 'tasks', 'run', 'csv_to_star_schema_to_s3_to_redshift', 'create_or_replace_fact_sales_table', 'manual__2024-10-07T12:52:42.125159+00:00', '--job-id', '118', '--raw', '--subdir', 'DAGS_FOLDER/sales_pipeline.py', '--cfg-path', '/tmp/tmpyk5suwbi']
[2024-10-07T12:52:50.336+0000] {standard_task_runner.py:105} INFO - Job 118: Subtask create_or_replace_fact_sales_table
[2024-10-07T12:52:50.347+0000] {logging_mixin.py:190} WARNING - /home/***/.local/lib/python3.12/site-packages/***/settings.py:209 DeprecationWarning: The sql_alchemy_conn option in [core] has been moved to the sql_alchemy_conn option in [database] - the old setting has been used, but please update your config.
[2024-10-07T12:52:50.364+0000] {task_command.py:467} INFO - Running <TaskInstance: csv_to_star_schema_to_s3_to_redshift.create_or_replace_fact_sales_table manual__2024-10-07T12:52:42.125159+00:00 [running]> on host 66045655c750
[2024-10-07T12:52:50.413+0000] {taskinstance.py:3131} INFO - Exporting env vars: AIRFLOW_CTX_DAG_OWNER='***' AIRFLOW_CTX_DAG_ID='csv_to_star_schema_to_s3_to_redshift' AIRFLOW_CTX_TASK_ID='create_or_replace_fact_sales_table' AIRFLOW_CTX_EXECUTION_DATE='2024-10-07T12:52:42.125159+00:00' AIRFLOW_CTX_TRY_NUMBER='1' AIRFLOW_CTX_DAG_RUN_ID='manual__2024-10-07T12:52:42.125159+00:00'
[2024-10-07T12:52:50.414+0000] {taskinstance.py:731} INFO - ::endgroup::
[2024-10-07T12:52:50.422+0000] {sql.py:266} INFO - Executing: 
        CREATE TABLE IF NOT EXISTS etl_data.fact_sales (
            customer_key INT, product_key INT, date_key INT, Time VARCHAR(255), Aging FLOAT, Device_Type VARCHAR(255), Sales FLOAT, Quantity FLOAT, Discount FLOAT, Profit FLOAT, Shipping_Cost FLOAT, Order_Priority VARCHAR(255), Payment_method VARCHAR(255), Profit_Margin FLOAT, Profit_Margin_Category VARCHAR(255), Total_Revenue FLOAT
        );
        TRUNCATE TABLE etl_data.fact_sales;
        
[2024-10-07T12:52:50.429+0000] {base.py:84} INFO - Retrieving connection 'redshift_default'
[2024-10-07T12:52:50.434+0000] {base.py:84} INFO - Retrieving connection 'redshift_default'
[2024-10-07T12:52:50.438+0000] {base.py:84} INFO - Retrieving connection 'aws_default'
[2024-10-07T12:52:50.439+0000] {connection_wrapper.py:388} INFO - AWS Connection (conn_id='aws_default', conn_type='aws') credentials retrieved from login and password.
[2024-10-07T12:52:51.696+0000] {credentials.py:1147} INFO - Found credentials in environment variables.
[2024-10-07T12:52:53.474+0000] {sql.py:509} INFO - Running statement: 
        CREATE TABLE IF NOT EXISTS etl_data.fact_sales (
            customer_key INT, product_key INT, date_key INT, Time VARCHAR(255), Aging FLOAT, Device_Type VARCHAR(255), Sales FLOAT, Quantity FLOAT, Discount FLOAT, Profit FLOAT, Shipping_Cost FLOAT, Order_Priority VARCHAR(255), Payment_method VARCHAR(255), Profit_Margin FLOAT, Profit_Margin_Category VARCHAR(255), Total_Revenue FLOAT
        );
        TRUNCATE TABLE etl_data.fact_sales;
        , parameters: None
[2024-10-07T12:52:53.821+0000] {taskinstance.py:3310} ERROR - Task failed with exception
Traceback (most recent call last):
  File "/home/airflow/.local/lib/python3.12/site-packages/redshift_connector/core.py", line 1830, in execute
    ps = cache["ps"][key]
         ~~~~~~~~~~~^^^^^
KeyError: ('\n        CREATE TABLE IF NOT EXISTS etl_data.fact_sales (\n            customer_key INT, product_key INT, date_key INT, Time VARCHAR(255), Aging FLOAT, Device_Type VARCHAR(255), Sales FLOAT, Quantity FLOAT, Discount FLOAT, Profit FLOAT, Shipping_Cost FLOAT, Order_Priority VARCHAR(255), Payment_method VARCHAR(255), Profit_Margin FLOAT, Profit_Margin_Category VARCHAR(255), Total_Revenue FLOAT\n        );\n        TRUNCATE TABLE etl_data.fact_sales;\n        ', ())

During handling of the above exception, another exception occurred:

Traceback (most recent call last):
  File "/home/airflow/.local/lib/python3.12/site-packages/airflow/models/taskinstance.py", line 767, in _execute_task
    result = _execute_callable(context=context, **execute_callable_kwargs)
             ^^^^^^^^^^^^^^^^^^^^^^^^^^^^^^^^^^^^^^^^^^^^^^^^^^^^^^^^^^^^^
  File "/home/airflow/.local/lib/python3.12/site-packages/airflow/models/taskinstance.py", line 733, in _execute_callable
    return ExecutionCallableRunner(
           ^^^^^^^^^^^^^^^^^^^^^^^^
  File "/home/airflow/.local/lib/python3.12/site-packages/airflow/utils/operator_helpers.py", line 252, in run
    return self.func(*args, **kwargs)
           ^^^^^^^^^^^^^^^^^^^^^^^^^^
  File "/home/airflow/.local/lib/python3.12/site-packages/airflow/models/baseoperator.py", line 406, in wrapper
    return func(self, *args, **kwargs)
           ^^^^^^^^^^^^^^^^^^^^^^^^^^^
  File "/home/airflow/.local/lib/python3.12/site-packages/airflow/providers/common/sql/operators/sql.py", line 272, in execute
    output = hook.run(
             ^^^^^^^^^
  File "/home/airflow/.local/lib/python3.12/site-packages/airflow/providers/common/sql/hooks/sql.py", line 456, in run
    self._run_command(cur, sql_statement, parameters)
  File "/home/airflow/.local/lib/python3.12/site-packages/airflow/providers/common/sql/hooks/sql.py", line 514, in _run_command
    cur.execute(sql_statement)
  File "/home/airflow/.local/lib/python3.12/site-packages/redshift_connector/cursor.py", line 248, in execute
    raise e
  File "/home/airflow/.local/lib/python3.12/site-packages/redshift_connector/cursor.py", line 241, in execute
    self._c.execute(self, operation, args)
  File "/home/airflow/.local/lib/python3.12/site-packages/redshift_connector/core.py", line 1911, in execute
    self.handle_messages(cursor)
  File "/home/airflow/.local/lib/python3.12/site-packages/redshift_connector/core.py", line 2203, in handle_messages
    raise self.error
redshift_connector.error.ProgrammingError: {'S': 'ERROR', 'C': '42601', 'M': 'cannot insert multiple commands into a prepared statement', 'F': '/home/ec2-user/padb/src/pg/src/backend/tcop/postgres.c', 'L': '4287', 'R': 'exec_parse_message'}
[2024-10-07T12:52:53.828+0000] {taskinstance.py:1225} INFO - Marking task as UP_FOR_RETRY. dag_id=csv_to_star_schema_to_s3_to_redshift, task_id=create_or_replace_fact_sales_table, run_id=manual__2024-10-07T12:52:42.125159+00:00, execution_date=20241007T125242, start_date=20241007T125250, end_date=20241007T125253
[2024-10-07T12:52:53.838+0000] {taskinstance.py:340} INFO - ::group::Post task execution logs
[2024-10-07T12:52:53.839+0000] {standard_task_runner.py:124} ERROR - Failed to execute job 118 for task create_or_replace_fact_sales_table ({'S': 'ERROR', 'C': '42601', 'M': 'cannot insert multiple commands into a prepared statement', 'F': '/home/ec2-user/padb/src/pg/src/backend/tcop/postgres.c', 'L': '4287', 'R': 'exec_parse_message'}; 10730)
Traceback (most recent call last):
  File "/home/airflow/.local/lib/python3.12/site-packages/redshift_connector/core.py", line 1830, in execute
    ps = cache["ps"][key]
         ~~~~~~~~~~~^^^^^
KeyError: ('\n        CREATE TABLE IF NOT EXISTS etl_data.fact_sales (\n            customer_key INT, product_key INT, date_key INT, Time VARCHAR(255), Aging FLOAT, Device_Type VARCHAR(255), Sales FLOAT, Quantity FLOAT, Discount FLOAT, Profit FLOAT, Shipping_Cost FLOAT, Order_Priority VARCHAR(255), Payment_method VARCHAR(255), Profit_Margin FLOAT, Profit_Margin_Category VARCHAR(255), Total_Revenue FLOAT\n        );\n        TRUNCATE TABLE etl_data.fact_sales;\n        ', ())

During handling of the above exception, another exception occurred:

Traceback (most recent call last):
  File "/home/airflow/.local/lib/python3.12/site-packages/airflow/task/task_runner/standard_task_runner.py", line 117, in _start_by_fork
    ret = args.func(args, dag=self.dag)
          ^^^^^^^^^^^^^^^^^^^^^^^^^^^^^
  File "/home/airflow/.local/lib/python3.12/site-packages/airflow/cli/cli_config.py", line 49, in command
    return func(*args, **kwargs)
           ^^^^^^^^^^^^^^^^^^^^^
  File "/home/airflow/.local/lib/python3.12/site-packages/airflow/utils/cli.py", line 115, in wrapper
    return f(*args, **kwargs)
           ^^^^^^^^^^^^^^^^^^
  File "/home/airflow/.local/lib/python3.12/site-packages/airflow/cli/commands/task_command.py", line 483, in task_run
    task_return_code = _run_task_by_selected_method(args, _dag, ti)
                       ^^^^^^^^^^^^^^^^^^^^^^^^^^^^^^^^^^^^^^^^^^^^
  File "/home/airflow/.local/lib/python3.12/site-packages/airflow/cli/commands/task_command.py", line 256, in _run_task_by_selected_method
    return _run_raw_task(args, ti)
           ^^^^^^^^^^^^^^^^^^^^^^^
  File "/home/airflow/.local/lib/python3.12/site-packages/airflow/cli/commands/task_command.py", line 341, in _run_raw_task
    return ti._run_raw_task(
           ^^^^^^^^^^^^^^^^^
  File "/home/airflow/.local/lib/python3.12/site-packages/airflow/utils/session.py", line 97, in wrapper
    return func(*args, session=session, **kwargs)
           ^^^^^^^^^^^^^^^^^^^^^^^^^^^^^^^^^^^^^^
  File "/home/airflow/.local/lib/python3.12/site-packages/airflow/models/taskinstance.py", line 3004, in _run_raw_task
    return _run_raw_task(
           ^^^^^^^^^^^^^^
  File "/home/airflow/.local/lib/python3.12/site-packages/airflow/models/taskinstance.py", line 273, in _run_raw_task
    TaskInstance._execute_task_with_callbacks(
  File "/home/airflow/.local/lib/python3.12/site-packages/airflow/models/taskinstance.py", line 3158, in _execute_task_with_callbacks
    result = self._execute_task(context, task_orig)
             ^^^^^^^^^^^^^^^^^^^^^^^^^^^^^^^^^^^^^^
  File "/home/airflow/.local/lib/python3.12/site-packages/airflow/models/taskinstance.py", line 3182, in _execute_task
    return _execute_task(self, context, task_orig)
           ^^^^^^^^^^^^^^^^^^^^^^^^^^^^^^^^^^^^^^^
  File "/home/airflow/.local/lib/python3.12/site-packages/airflow/models/taskinstance.py", line 767, in _execute_task
    result = _execute_callable(context=context, **execute_callable_kwargs)
             ^^^^^^^^^^^^^^^^^^^^^^^^^^^^^^^^^^^^^^^^^^^^^^^^^^^^^^^^^^^^^
  File "/home/airflow/.local/lib/python3.12/site-packages/airflow/models/taskinstance.py", line 733, in _execute_callable
    return ExecutionCallableRunner(
           ^^^^^^^^^^^^^^^^^^^^^^^^
  File "/home/airflow/.local/lib/python3.12/site-packages/airflow/utils/operator_helpers.py", line 252, in run
    return self.func(*args, **kwargs)
           ^^^^^^^^^^^^^^^^^^^^^^^^^^
  File "/home/airflow/.local/lib/python3.12/site-packages/airflow/models/baseoperator.py", line 406, in wrapper
    return func(self, *args, **kwargs)
           ^^^^^^^^^^^^^^^^^^^^^^^^^^^
  File "/home/airflow/.local/lib/python3.12/site-packages/airflow/providers/common/sql/operators/sql.py", line 272, in execute
    output = hook.run(
             ^^^^^^^^^
  File "/home/airflow/.local/lib/python3.12/site-packages/airflow/providers/common/sql/hooks/sql.py", line 456, in run
    self._run_command(cur, sql_statement, parameters)
  File "/home/airflow/.local/lib/python3.12/site-packages/airflow/providers/common/sql/hooks/sql.py", line 514, in _run_command
    cur.execute(sql_statement)
  File "/home/airflow/.local/lib/python3.12/site-packages/redshift_connector/cursor.py", line 248, in execute
    raise e
  File "/home/airflow/.local/lib/python3.12/site-packages/redshift_connector/cursor.py", line 241, in execute
    self._c.execute(self, operation, args)
  File "/home/airflow/.local/lib/python3.12/site-packages/redshift_connector/core.py", line 1911, in execute
    self.handle_messages(cursor)
  File "/home/airflow/.local/lib/python3.12/site-packages/redshift_connector/core.py", line 2203, in handle_messages
    raise self.error
redshift_connector.error.ProgrammingError: {'S': 'ERROR', 'C': '42601', 'M': 'cannot insert multiple commands into a prepared statement', 'F': '/home/ec2-user/padb/src/pg/src/backend/tcop/postgres.c', 'L': '4287', 'R': 'exec_parse_message'}
[2024-10-07T12:52:53.880+0000] {local_task_job_runner.py:266} INFO - Task exited with return code 1
[2024-10-07T12:52:53.893+0000] {taskinstance.py:3900} INFO - 0 downstream tasks scheduled from follow-on schedule check
[2024-10-07T12:52:53.896+0000] {local_task_job_runner.py:245} INFO - ::endgroup::
